Workbook

Sheet Instruktion
A1: Arbetsgång energideklaration enligt BFS 2026:9 och 2026:10
A3: 1 | B3: Byggnader: fyll i fastighet, kommun och mätperiod. En kolumn per fysisk byggnad med typ, antal lägenheter, summerad A-temp för bostäder, lokaler per kategori och varmgarage.
A4: 2 | B4: Mätdata: lägg in varje energimätare med energibärare, ändamål och vilken byggnad den försörjer. Välj Alla för gemensamma mätare, t.ex. en fjärrvärmecentral med kulvert. Lägg in vattenmätare på samma sätt.
A5: 3 | B5: Mätdata: ange andel varmvattenproduktion och årsverkningsgrad per värmekälla, kulvertförluster och hur de ska hanteras. Fastighetselen hämtas från besiktningsprotokollets sammanställning och fördelas efter A-temp.
A6: 4 | B6: Byggnader: kontrollera fördelningsnycklarna för gemensamma mätare. Ange manuell andel om A-temp eller antal lägenheter inte speglar verkligheten.
A7: 5 | B7: Besiktningsprotokoll: fyll i som tidigare. Summan av fastighetsel (D125) blir fastighetens fastighetsel inom systemgräns.
A8: 6 | B8: Normalisering: ange faktisk innetemperatur, uteluftsflöde, återvinning och personer per lägenhet per byggnad, och välj Ja/Nej för de fyra normaliseringarna.
A9: 7 | B9: Resultat: kontrollera energiprestandatal och energiklass per byggnad. Ange samma energiindex i Byggnader C10 som Gripen använder för att värdena ska stämma.
A10: 8 | B10: Gripen: välj byggnad i B4 och för över de grå cellerna avsnitt för avsnitt. Upprepa för varje byggnad. Jämför sedan Gripens beräkning med kontrollvärdena.
A11: 9 | B11: Åtgärdsflikarna fungerar som tidigare för hela fastigheten. Fliken Övrig åtgärd används för andra åtgärder: ange namn i A1, investering och ändrad värme- och elförbrukning. Besparingen fördelas per byggnad i fliken Gripen.
A12: 10 | B12: Solceller: ange installerad effekt per byggnad och produktion och såld el, per byggnad eller för hela fastigheten. Egenanvänd solel fördelas automatiskt på förbrukarna efter årsförbrukning. Samtidighetsfaktorn (standard 1,0) kan justeras om det finns skäl.
A13: 11 | B13: Fliken Tidigare deklarationer fylls av webbverktyget som läser in gamla energideklarationer. Kontrollera A-temp, verksamhetsfördelning och byggnadstyp mot de nya kategorierna.

Sheet Sammanfattning
A1: Sammanfattning – Energideklaration
A2: Byggnad | B2: =IF(Besiktningsprotokoll!B4="","",Besiktningsprotokoll!B4)
A3: Adress | B3: =IF(Besiktningsprotokoll!B5="","",Besiktningsprotokoll!B5)
A4: Utförd av | B4: =Besiktningsprotokoll!D3&" ("&Besiktningsprotokoll!D4&")" -> Peter Persson (HSB Värmland)
A6: 1. Nuvarande energianvändning
A7: Kategori | B7: kWh/år | C7: Andel
A8: Värme (uppvärmning, normaliserad, ej klimatkorrigerad) | B8: =Normalisering!I120 -> 0 | C8: =B8/$B$12 -> #DIV/0!
A9: Varmvatten (normaliserat) | B9: =Normalisering!I132 -> 0 | C9: =B9/$B$12 -> #DIV/0!
A10: Fastighetsel inom systemgräns (netto) | B10: =Normalisering!I139 -> 0 | C10: =B10/$B$12 -> #DIV/0!
A11: Verksamhetsel | B11: =Normalisering!I144 -> 0 | C11: =B11/$B$12 -> #DIV/0!
A12: Summa | B12: =SUM(B8:B11) -> 0 | C12: 1
A13: Summor för hela fastigheten. Resultat per byggnad finns i flikarna Resultat och Gripen.
A14: Energiprestandatal fastigheten (kWh/m²,år) | B14: =Resultat!I13
A15: Energiklass fastigheten (BFS 2026:10) | B15: =Resultat!I24
A16: 2. Föreslagna energiåtgärder
A17: Markera "Ja" i respektive åtgärdsflik (cell B2). Aktiverade åtgärder sorteras efter kortast paybacktid. Ej aktiverade åtgärder hamnar sist. | K17: Hjälptabell i fast ordning (används för sorteringen och fliken Gripen)
A18: Åtgärd | B18: Aktiverad | C18: Investering (kr) | D18: Energibesparing (kWh/år) | E18: Kostnadsbesparing (kr/år) | F18: Paybacktid (år) | G18: Lönsamhet | H18: Kommentar | K18: Åtgärd | L18: Aktiverad | M18: Investering (kr) | N18: Energibesparing (kWh/år) | O18: Kostnadsbesparing (kr/år) | P18: Paybacktid (år) | Q18: Lönsamhet | R18: Sorteringsnyckel
A19: =IFERROR(IF(INDEX($K$19:$K$29,MATCH(SMALL($R$19:$R$29,1),$R$19:$R$29,0))="","",INDEX($K$19:$K$29,MATCH(SMALL($R$19:$R$29,1),$R$19:$R$29,0))),"") -> Bergvärme | B19: =IFERROR(IF(INDEX($L$19:$L$29,MATCH(SMALL($R$19:$R$29,1),$R$19:$R$29,0))="","",INDEX($L$19:$L$29,MATCH(SMALL($R$19:$R$29,1),$R$19:$R$29,0))),"") -> Nej | C19: =IFERROR(IF(INDEX($M$19:$M$29,MATCH(SMALL($R$19:$R$29,1),$R$19:$R$29,0))="","",INDEX($M$19:$M$29,MATCH(SMALL($R$19:$R$29,1),$R$19:$R$29,0))),"") | D19: =IFERROR(IF(INDEX($N$19:$N$29,MATCH(SMALL($R$19:$R$29,1),$R$19:$R$29,0))="","",INDEX($N$19:$N$29,MATCH(SMALL($R$19:$R$29,1),$R$19:$R$29,0))),"") | E19: =IFERROR(IF(INDEX($O$19:$O$29,MATCH(SMALL($R$19:$R$29,1),$R$19:$R$29,0))="","",INDEX($O$19:$O$29,MATCH(SMALL($R$19:$R$29,1),$R$19:$R$29,0))),"") | F19: =IFERROR(IF(INDEX($P$19:$P$29,MATCH(SMALL($R$19:$R$29,1),$R$19:$R$29,0))="","",INDEX($P$19:$P$29,MATCH(SMALL($R$19:$R$29,1),$R$19:$R$29,0))),"") | G19: =IFERROR(IF(INDEX($Q$19:$Q$29,MATCH(SMALL($R$19:$R$29,1),$R$19:$R$29,0))="","",INDEX($Q$19:$Q$29,MATCH(SMALL($R$19:$R$29,1),$R$19:$R$29,0))),"") | H19: Utförs i samband med fasadrenovering | K19: ='Installera bergvärme'!A1 -> Bergvärme | L19: ='Installera bergvärme'!B2 -> Nej | M19: =IFERROR(IF('Installera bergvärme'!B2="Ja",'Installera bergvärme'!D20,""),"") | N19: =IFERROR(IF('Installera bergvärme'!B2="Ja",'Installera bergvärme'!C35-'Installera bergvärme'!D35,""),"") | O19: =IFERROR(IF('Installera bergvärme'!B2="Ja",'Installera bergvärme'!C34-'Installera bergvärme'!D34,""),"") | P19: =IFERROR(IF('Installera bergvärme'!B2="Ja",'Installera bergvärme'!E6,""),"") | Q19: =IFERROR(IF('Installera bergvärme'!B2="Ja",'Installera bergvärme'!D43,""),"") | R19: =IF(L19="Ja",IF(AND(ISNUMBER(P19),N(P19)>=0),P19,1000000),2000000)+ROW()/1000000 -> 2000000
A20: =IFERROR(IF(INDEX($K$19:$K$29,MATCH(SMALL($R$19:$R$29,2),$R$19:$R$29,0))="","",INDEX($K$19:$K$29,MATCH(SMALL($R$19:$R$29,2),$R$19:$R$29,0))),"") -> Injustering av värmesystem | B20: =IFERROR(IF(INDEX($L$19:$L$29,MATCH(SMALL($R$19:$R$29,2),$R$19:$R$29,0))="","",INDEX($L$19:$L$29,MATCH(SMALL($R$19:$R$29,2),$R$19:$R$29,0))),"") -> Nej | C20: =IFERROR(IF(INDEX($M$19:$M$29,MATCH(SMALL($R$19:$R$29,2),$R$19:$R$29,0))="","",INDEX($M$19:$M$29,MATCH(SMALL($R$19:$R$29,2),$R$19:$R$29,0))),"") | D20: =IFERROR(IF(INDEX($N$19:$N$29,MATCH(SMALL($R$19:$R$29,2),$R$19:$R$29,0))="","",INDEX($N$19:$N$29,MATCH(SMALL($R$19:$R$29,2),$R$19:$R$29,0))),"") | E20: =IFERROR(IF(INDEX($O$19:$O$29,MATCH(SMALL($R$19:$R$29,2),$R$19:$R$29,0))="","",INDEX($O$19:$O$29,MATCH(SMALL($R$19:$R$29,2),$R$19:$R$29,0))),"") | F20: =IFERROR(IF(INDEX($P$19:$P$29,MATCH(SMALL($R$19:$R$29,2),$R$19:$R$29,0))="","",INDEX($P$19:$P$29,MATCH(SMALL($R$19:$R$29,2),$R$19:$R$29,0))),"") | G20: =IFERROR(IF(INDEX($Q$19:$Q$29,MATCH(SMALL($R$19:$R$29,2),$R$19:$R$29,0))="","",INDEX($Q$19:$Q$29,MATCH(SMALL($R$19:$R$29,2),$R$19:$R$29,0))),"") | H20: Utförs med framtida underhållsbyte av frånluftsfläktar | K20: ='Injustering av värmesystem'!A1 -> Injustering av värmesystem | L20: ='Injustering av värmesystem'!B2 -> Nej | M20: =IFERROR(IF('Injustering av värmesystem'!B2="Ja",'Injustering av värmesystem'!D20,""),"") | N20: =IFERROR(IF('Injustering av värmesystem'!B2="Ja",'Injustering av värmesystem'!C35-'Injustering av värmesystem'!D35,""),"") | O20: =IFERROR(IF('Injustering av värmesystem'!B2="Ja",'Injustering av värmesystem'!C34-'Injustering av värmesystem'!D34,""),"") | P20: =IFERROR(IF('Injustering av värmesystem'!B2="Ja",'Injustering av värmesystem'!E6,""),"") | Q20: =IFERROR(IF('Injustering av värmesystem'!B2="Ja",'Injustering av värmesystem'!D43,""),"") | R20: =IF(L20="Ja",IF(AND(ISNUMBER(P20),N(P20)>=0),P20,1000000),2000000)+ROW()/1000000 -> 2000000
A21: =IFERROR(IF(INDEX($K$19:$K$29,MATCH(SMALL($R$19:$R$29,3),$R$19:$R$29,0))="","",INDEX($K$19:$K$29,MATCH(SMALL($R$19:$R$29,3),$R$19:$R$29,0))),"") -> Byte styrsystem för värme | B21: =IFERROR(IF(INDEX($L$19:$L$29,MATCH(SMALL($R$19:$R$29,3),$R$19:$R$29,0))="","",INDEX($L$19:$L$29,MATCH(SMALL($R$19:$R$29,3),$R$19:$R$29,0))),"") -> Nej | C21: =IFERROR(IF(INDEX($M$19:$M$29,MATCH(SMALL($R$19:$R$29,3),$R$19:$R$29,0))="","",INDEX($M$19:$M$29,MATCH(SMALL($R$19:$R$29,3),$R$19:$R$29,0))),"") | D21: =IFERROR(IF(INDEX($N$19:$N$29,MATCH(SMALL($R$19:$R$29,3),$R$19:$R$29,0))="","",INDEX($N$19:$N$29,MATCH(SMALL($R$19:$R$29,3),$R$19:$R$29,0))),"") | E21: =IFERROR(IF(INDEX($O$19:$O$29,MATCH(SMALL($R$19:$R$29,3),$R$19:$R$29,0))="","",INDEX($O$19:$O$29,MATCH(SMALL($R$19:$R$29,3),$R$19:$R$29,0))),"") | F21: =IFERROR(IF(INDEX($P$19:$P$29,MATCH(SMALL($R$19:$R$29,3),$R$19:$R$29,0))="","",INDEX($P$19:$P$29,MATCH(SMALL($R$19:$R$29,3),$R$19:$R$29,0))),"") | G21: =IFERROR(IF(INDEX($Q$19:$Q$29,MATCH(SMALL($R$19:$R$29,3),$R$19:$R$29,0))="","",INDEX($Q$19:$Q$29,MATCH(SMALL($R$19:$R$29,3),$R$19:$R$29,0))),"") | K21: ='Styrsystem för värme'!A1 -> Byte styrsystem för värme | L21: ='Styrsystem för värme'!B2 -> Nej | M21: =IFERROR(IF('Styrsystem för värme'!B2="Ja",'Styrsystem för värme'!D20,""),"") | N21: =IFERROR(IF('Styrsystem för värme'!B2="Ja",'Styrsystem för värme'!C35-'Styrsystem för värme'!D35,""),"") | O21: =IFERROR(IF('Styrsystem för värme'!B2="Ja",'Styrsystem för värme'!C34-'Styrsystem för värme'!D34,""),"") | P21: =IFERROR(IF('Styrsystem för värme'!B2="Ja",'Styrsystem för värme'!E6,""),"") | Q21: =IFERROR(IF('Styrsystem för värme'!B2="Ja",'Styrsystem för värme'!D43,""),"") | R21: =IF(L21="Ja",IF(AND(ISNUMBER(P21),N(P21)>=0),P21,1000000),2000000)+ROW()/1000000 -> 2000000
A22: =IFERROR(IF(INDEX($K$19:$K$29,MATCH(SMALL($R$19:$R$29,4),$R$19:$R$29,0))="","",INDEX($K$19:$K$29,MATCH(SMALL($R$19:$R$29,4),$R$19:$R$29,0))),"") -> Tilläggisolering av vindbjälklaget | B22: =IFERROR(IF(INDEX($L$19:$L$29,MATCH(SMALL($R$19:$R$29,4),$R$19:$R$29,0))="","",INDEX($L$19:$L$29,MATCH(SMALL($R$19:$R$29,4),$R$19:$R$29,0))),"") -> Nej | C22: =IFERROR(IF(INDEX($M$19:$M$29,MATCH(SMALL($R$19:$R$29,4),$R$19:$R$29,0))="","",INDEX($M$19:$M$29,MATCH(SMALL($R$19:$R$29,4),$R$19:$R$29,0))),"") | D22: =IFERROR(IF(INDEX($N$19:$N$29,MATCH(SMALL($R$19:$R$29,4),$R$19:$R$29,0))="","",INDEX($N$19:$N$29,MATCH(SMALL($R$19:$R$29,4),$R$19:$R$29,0))),"") | E22: =IFERROR(IF(INDEX($O$19:$O$29,MATCH(SMALL($R$19:$R$29,4),$R$19:$R$29,0))="","",INDEX($O$19:$O$29,MATCH(SMALL($R$19:$R$29,4),$R$19:$R$29,0))),"") | F22: =IFERROR(IF(INDEX($P$19:$P$29,MATCH(SMALL($R$19:$R$29,4),$R$19:$R$29,0))="","",INDEX($P$19:$P$29,MATCH(SMALL($R$19:$R$29,4),$R$19:$R$29,0))),"") | G22: =IFERROR(IF(INDEX($Q$19:$Q$29,MATCH(SMALL($R$19:$R$29,4),$R$19:$R$29,0))="","",INDEX($Q$19:$Q$29,MATCH(SMALL($R$19:$R$29,4),$R$19:$R$29,0))),"") | K22: ='Tilläggisolering av vindsbjälk'!A1 -> Tilläggisolering av vindbjälklaget | L22: ='Tilläggisolering av vindsbjälk'!B2 -> Nej | M22: =IFERROR(IF('Tilläggisolering av vindsbjälk'!B2="Ja",'Tilläggisolering av vindsbjälk'!D20,""),"") | N22: =IFERROR(IF('Tilläggisolering av vindsbjälk'!B2="Ja",'Tilläggisolering av vindsbjälk'!C35-'Tilläggisolering av vindsbjälk'!D35,""),"") | O22: =IFERROR(IF('Tilläggisolering av vindsbjälk'!B2="Ja",'Tilläggisolering av vindsbjälk'!C34-'Tilläggisolering av vindsbjälk'!D34,""),"") | P22: =IFERROR(IF('Tilläggisolering av vindsbjälk'!B2="Ja",'Tilläggisolering av vindsbjälk'!E6,""),"") | Q22: =IFERROR(IF('Tilläggisolering av vindsbjälk'!B2="Ja",'Tilläggisolering av vindsbjälk'!D43,""),"") | R22: =IF(L22="Ja",IF(AND(ISNUMBER(P22),N(P22)>=0),P22,1000000),2000000)+ROW()/1000000 -> 2000000
A23: =IFERROR(IF(INDEX($K$19:$K$29,MATCH(SMALL($R$19:$R$29,5),$R$19:$R$29,0))="","",INDEX($K$19:$K$29,MATCH(SMALL($R$19:$R$29,5),$R$19:$R$29,0))),"") -> Byte av fönster | B23: =IFERROR(IF(INDEX($L$19:$L$29,MATCH(SMALL($R$19:$R$29,5),$R$19:$R$29,0))="","",INDEX($L$19:$L$29,MATCH(SMALL($R$19:$R$29,5),$R$19:$R$29,0))),"") -> Nej | C23: =IFERROR(IF(INDEX($M$19:$M$29,MATCH(SMALL($R$19:$R$29,5),$R$19:$R$29,0))="","",INDEX($M$19:$M$29,MATCH(SMALL($R$19:$R$29,5),$R$19:$R$29,0))),"") | D23: =IFERROR(IF(INDEX($N$19:$N$29,MATCH(SMALL($R$19:$R$29,5),$R$19:$R$29,0))="","",INDEX($N$19:$N$29,MATCH(SMALL($R$19:$R$29,5),$R$19:$R$29,0))),"") | E23: =IFERROR(IF(INDEX($O$19:$O$29,MATCH(SMALL($R$19:$R$29,5),$R$19:$R$29,0))="","",INDEX($O$19:$O$29,MATCH(SMALL($R$19:$R$29,5),$R$19:$R$29,0))),"") | F23: =IFERROR(IF(INDEX($P$19:$P$29,MATCH(SMALL($R$19:$R$29,5),$R$19:$R$29,0))="","",INDEX($P$19:$P$29,MATCH(SMALL($R$19:$R$29,5),$R$19:$R$29,0))),"") | G23: =IFERROR(IF(INDEX($Q$19:$Q$29,MATCH(SMALL($R$19:$R$29,5),$R$19:$R$29,0))="","",INDEX($Q$19:$Q$29,MATCH(SMALL($R$19:$R$29,5),$R$19:$R$29,0))),"") | K23: ='Byte fönster'!A1 -> Byte av fönster | L23: ='Byte fönster'!B2 -> Nej | M23: =IFERROR(IF('Byte fönster'!B2="Ja",'Byte fönster'!D20,""),"") | N23: =IFERROR(IF('Byte fönster'!B2="Ja",'Byte fönster'!C35-'Byte fönster'!D35,""),"") | O23: =IFERROR(IF('Byte fönster'!B2="Ja",'Byte fönster'!C34-'Byte fönster'!D34,""),"") | P23: =IFERROR(IF('Byte fönster'!B2="Ja",'Byte fönster'!E6,""),"") | Q23: =IFERROR(IF('Byte fönster'!B2="Ja",'Byte fönster'!D43,""),"") | R23: =IF(L23="Ja",IF(AND(ISNUMBER(P23),N(P23)>=0),P23,1000000),2000000)+ROW()/1000000 -> 2000000
A24: =IFERROR(IF(INDEX($K$19:$K$29,MATCH(SMALL($R$19:$R$29,6),$R$19:$R$29,0))="","",INDEX($K$19:$K$29,MATCH(SMALL($R$19:$R$29,6),$R$19:$R$29,0))),"") -> Tilläggisolering av fasader | B24: =IFERROR(IF(INDEX($L$19:$L$29,MATCH(SMALL($R$19:$R$29,6),$R$19:$R$29,0))="","",INDEX($L$19:$L$29,MATCH(SMALL($R$19:$R$29,6),$R$19:$R$29,0))),"") -> Nej | C24: =IFERROR(IF(INDEX($M$19:$M$29,MATCH(SMALL($R$19:$R$29,6),$R$19:$R$29,0))="","",INDEX($M$19:$M$29,MATCH(SMALL($R$19:$R$29,6),$R$19:$R$29,0))),"") | D24: =IFERROR(IF(INDEX($N$19:$N$29,MATCH(SMALL($R$19:$R$29,6),$R$19:$R$29,0))="","",INDEX($N$19:$N$29,MATCH(SMALL($R$19:$R$29,6),$R$19:$R$29,0))),"") | E24: =IFERROR(IF(INDEX($O$19:$O$29,MATCH(SMALL($R$19:$R$29,6),$R$19:$R$29,0))="","",INDEX($O$19:$O$29,MATCH(SMALL($R$19:$R$29,6),$R$19:$R$29,0))),"") | F24: =IFERROR(IF(INDEX($P$19:$P$29,MATCH(SMALL($R$19:$R$29,6),$R$19:$R$29,0))="","",INDEX($P$19:$P$29,MATCH(SMALL($R$19:$R$29,6),$R$19:$R$29,0))),"") | G24: =IFERROR(IF(INDEX($Q$19:$Q$29,MATCH(SMALL($R$19:$R$29,6),$R$19:$R$29,0))="","",INDEX($Q$19:$Q$29,MATCH(SMALL($R$19:$R$29,6),$R$19:$R$29,0))),"") | K24: ='Tilläggisol fasad'!A1 -> Tilläggisolering av fasader | L24: ='Tilläggisol fasad'!B2 -> Nej | M24: =IFERROR(IF('Tilläggisol fasad'!B2="Ja",'Tilläggisol fasad'!D20,""),"") | N24: =IFERROR(IF('Tilläggisol fasad'!B2="Ja",'Tilläggisol fasad'!C35-'Tilläggisol fasad'!D35,""),"") | O24: =IFERROR(IF('Tilläggisol fasad'!B2="Ja",'Tilläggisol fasad'!C34-'Tilläggisol fasad'!D34,""),"") | P24: =IFERROR(IF('Tilläggisol fasad'!B2="Ja",'Tilläggisol fasad'!E6,""),"") | Q24: =IFERROR(IF('Tilläggisol fasad'!B2="Ja",'Tilläggisol fasad'!D43,""),"") | R24: =IF(L24="Ja",IF(AND(ISNUMBER(P24),N(P24)>=0),P24,1000000),2000000)+ROW()/1000000 -> 2000000
A25: =IFERROR(IF(INDEX($K$19:$K$29,MATCH(SMALL($R$19:$R$29,7),$R$19:$R$29,0))="","",INDEX($K$19:$K$29,MATCH(SMALL($R$19:$R$29,7),$R$19:$R$29,0))),"") -> Installation av frånluftsåtervinning | B25: =IFERROR(IF(INDEX($L$19:$L$29,MATCH(SMALL($R$19:$R$29,7),$R$19:$R$29,0))="","",INDEX($L$19:$L$29,MATCH(SMALL($R$19:$R$29,7),$R$19:$R$29,0))),"") -> Nej | C25: =IFERROR(IF(INDEX($M$19:$M$29,MATCH(SMALL($R$19:$R$29,7),$R$19:$R$29,0))="","",INDEX($M$19:$M$29,MATCH(SMALL($R$19:$R$29,7),$R$19:$R$29,0))),"") | D25: =IFERROR(IF(INDEX($N$19:$N$29,MATCH(SMALL($R$19:$R$29,7),$R$19:$R$29,0))="","",INDEX($N$19:$N$29,MATCH(SMALL($R$19:$R$29,7),$R$19:$R$29,0))),"") | E25: =IFERROR(IF(INDEX($O$19:$O$29,MATCH(SMALL($R$19:$R$29,7),$R$19:$R$29,0))="","",INDEX($O$19:$O$29,MATCH(SMALL($R$19:$R$29,7),$R$19:$R$29,0))),"") | F25: =IFERROR(IF(INDEX($P$19:$P$29,MATCH(SMALL($R$19:$R$29,7),$R$19:$R$29,0))="","",INDEX($P$19:$P$29,MATCH(SMALL($R$19:$R$29,7),$R$19:$R$29,0))),"") | G25: =IFERROR(IF(INDEX($Q$19:$Q$29,MATCH(SMALL($R$19:$R$29,7),$R$19:$R$29,0))="","",INDEX($Q$19:$Q$29,MATCH(SMALL($R$19:$R$29,7),$R$19:$R$29,0))),"") | K25: ='Installation F-återvinning'!A1 -> Installation av frånluftsåtervinning | L25: ='Installation F-återvinning'!B2 -> Nej | M25: =IFERROR(IF('Installation F-återvinning'!B2="Ja",'Installation F-återvinning'!D20,""),"") | N25: =IFERROR(IF('Installation F-återvinning'!B2="Ja",'Installation F-återvinning'!C35-'Installation F-återvinning'!D35,""),"") | O25: =IFERROR(IF('Installation F-återvinning'!B2="Ja",'Installation F-återvinning'!C34-'Installation F-återvinning'!D34,""),"") | P25: =IFERROR(IF('Installation F-återvinning'!B2="Ja",'Installation F-återvinning'!E6,""),"") | Q25: =IFERROR(IF('Installation F-återvinning'!B2="Ja",'Installation F-återvinning'!D43,""),"") | R25: =IF(L25="Ja",IF(AND(ISNUMBER(P25),N(P25)>=0),P25,1000000),2000000)+ROW()/1000000 -> 2000000
A26: =IFERROR(IF(INDEX($K$19:$K$29,MATCH(SMALL($R$19:$R$29,8),$R$19:$R$29,0))="","",INDEX($K$19:$K$29,MATCH(SMALL($R$19:$R$29,8),$R$19:$R$29,0))),"") -> Installation av solceller på taket | B26: =IFERROR(IF(INDEX($L$19:$L$29,MATCH(SMALL($R$19:$R$29,8),$R$19:$R$29,0))="","",INDEX($L$19:$L$29,MATCH(SMALL($R$19:$R$29,8),$R$19:$R$29,0))),"") -> Nej | C26: =IFERROR(IF(INDEX($M$19:$M$29,MATCH(SMALL($R$19:$R$29,8),$R$19:$R$29,0))="","",INDEX($M$19:$M$29,MATCH(SMALL($R$19:$R$29,8),$R$19:$R$29,0))),"") | D26: =IFERROR(IF(INDEX($N$19:$N$29,MATCH(SMALL($R$19:$R$29,8),$R$19:$R$29,0))="","",INDEX($N$19:$N$29,MATCH(SMALL($R$19:$R$29,8),$R$19:$R$29,0))),"") | E26: =IFERROR(IF(INDEX($O$19:$O$29,MATCH(SMALL($R$19:$R$29,8),$R$19:$R$29,0))="","",INDEX($O$19:$O$29,MATCH(SMALL($R$19:$R$29,8),$R$19:$R$29,0))),"") | F26: =IFERROR(IF(INDEX($P$19:$P$29,MATCH(SMALL($R$19:$R$29,8),$R$19:$R$29,0))="","",INDEX($P$19:$P$29,MATCH(SMALL($R$19:$R$29,8),$R$19:$R$29,0))),"") | G26: =IFERROR(IF(INDEX($Q$19:$Q$29,MATCH(SMALL($R$19:$R$29,8),$R$19:$R$29,0))="","",INDEX($Q$19:$Q$29,MATCH(SMALL($R$19:$R$29,8),$R$19:$R$29,0))),"") | K26: ='Installation av solceller'!A1 -> Installation av solceller på taket | L26: ='Installation av solceller'!B2 -> Nej | M26: =IFERROR(IF('Installation av solceller'!B2="Ja",'Installation av solceller'!D20,""),"") | N26: =IFERROR(IF('Installation av solceller'!B2="Ja",'Installation av solceller'!C35-'Installation av solceller'!D35,""),"") | O26: =IFERROR(IF('Installation av solceller'!B2="Ja",'Installation av solceller'!C34-'Installation av solceller'!D34,""),"") | P26: =IFERROR(IF('Installation av solceller'!B2="Ja",'Installation av solceller'!E6,""),"") | Q26: =IFERROR(IF('Installation av solceller'!B2="Ja",'Installation av solceller'!D43,""),"") | R26: =IF(L26="Ja",IF(AND(ISNUMBER(P26),N(P26)>=0),P26,1000000),2000000)+ROW()/1000000 -> 2000000
A27: =IFERROR(IF(INDEX($K$19:$K$29,MATCH(SMALL($R$19:$R$29,9),$R$19:$R$29,0))="","",INDEX($K$19:$K$29,MATCH(SMALL($R$19:$R$29,9),$R$19:$R$29,0))),"") -> Byte av pump till tryckstyrd med bättre effektivitet | B27: =IFERROR(IF(INDEX($L$19:$L$29,MATCH(SMALL($R$19:$R$29,9),$R$19:$R$29,0))="","",INDEX($L$19:$L$29,MATCH(SMALL($R$19:$R$29,9),$R$19:$R$29,0))),"") -> Nej | C27: =IFERROR(IF(INDEX($M$19:$M$29,MATCH(SMALL($R$19:$R$29,9),$R$19:$R$29,0))="","",INDEX($M$19:$M$29,MATCH(SMALL($R$19:$R$29,9),$R$19:$R$29,0))),"") | D27: =IFERROR(IF(INDEX($N$19:$N$29,MATCH(SMALL($R$19:$R$29,9),$R$19:$R$29,0))="","",INDEX($N$19:$N$29,MATCH(SMALL($R$19:$R$29,9),$R$19:$R$29,0))),"") | E27: =IFERROR(IF(INDEX($O$19:$O$29,MATCH(SMALL($R$19:$R$29,9),$R$19:$R$29,0))="","",INDEX($O$19:$O$29,MATCH(SMALL($R$19:$R$29,9),$R$19:$R$29,0))),"") | F27: =IFERROR(IF(INDEX($P$19:$P$29,MATCH(SMALL($R$19:$R$29,9),$R$19:$R$29,0))="","",INDEX($P$19:$P$29,MATCH(SMALL($R$19:$R$29,9),$R$19:$R$29,0))),"") | G27: =IFERROR(IF(INDEX($Q$19:$Q$29,MATCH(SMALL($R$19:$R$29,9),$R$19:$R$29,0))="","",INDEX($Q$19:$Q$29,MATCH(SMALL($R$19:$R$29,9),$R$19:$R$29,0))),"") | K27: ='Byte av pump'!A1 -> Byte av pump till tryckstyrd med bättre effektivitet | L27: ='Byte av pump'!B2 -> Nej | M27: =IFERROR(IF('Byte av pump'!B2="Ja",'Byte av pump'!D20,""),"") | N27: =IFERROR(IF('Byte av pump'!B2="Ja",'Byte av pump'!C35-'Byte av pump'!D35,""),"") | O27: =IFERROR(IF('Byte av pump'!B2="Ja",'Byte av pump'!C34-'Byte av pump'!D34,""),"") | P27: =IFERROR(IF('Byte av pump'!B2="Ja",'Byte av pump'!E6,""),"") | Q27: =IFERROR(IF('Byte av pump'!B2="Ja",'Byte av pump'!D43,""),"") | R27: =IF(L27="Ja",IF(AND(ISNUMBER(P27),N(P27)>=0),P27,1000000),2000000)+ROW()/1000000 -> 2000000
A28: =IFERROR(IF(INDEX($K$19:$K$29,MATCH(SMALL($R$19:$R$29,10),$R$19:$R$29,0))="","",INDEX($K$19:$K$29,MATCH(SMALL($R$19:$R$29,10),$R$19:$R$29,0))),"") -> Byte av fläktar till tryckstyrd med bättre effektivitet | B28: =IFERROR(IF(INDEX($L$19:$L$29,MATCH(SMALL($R$19:$R$29,10),$R$19:$R$29,0))="","",INDEX($L$19:$L$29,MATCH(SMALL($R$19:$R$29,10),$R$19:$R$29,0))),"") -> Nej | C28: =IFERROR(IF(INDEX($M$19:$M$29,MATCH(SMALL($R$19:$R$29,10),$R$19:$R$29,0))="","",INDEX($M$19:$M$29,MATCH(SMALL($R$19:$R$29,10),$R$19:$R$29,0))),"") | D28: =IFERROR(IF(INDEX($N$19:$N$29,MATCH(SMALL($R$19:$R$29,10),$R$19:$R$29,0))="","",INDEX($N$19:$N$29,MATCH(SMALL($R$19:$R$29,10),$R$19:$R$29,0))),"") | E28: =IFERROR(IF(INDEX($O$19:$O$29,MATCH(SMALL($R$19:$R$29,10),$R$19:$R$29,0))="","",INDEX($O$19:$O$29,MATCH(SMALL($R$19:$R$29,10),$R$19:$R$29,0))),"") | F28: =IFERROR(IF(INDEX($P$19:$P$29,MATCH(SMALL($R$19:$R$29,10),$R$19:$R$29,0))="","",INDEX($P$19:$P$29,MATCH(SMALL($R$19:$R$29,10),$R$19:$R$29,0))),"") | G28: =IFERROR(IF(INDEX($Q$19:$Q$29,MATCH(SMALL($R$19:$R$29,10),$R$19:$R$29,0))="","",INDEX($Q$19:$Q$29,MATCH(SMALL($R$19:$R$29,10),$R$19:$R$29,0))),"") | K28: ='Byte av fläkt'!A1 -> Byte av fläktar till tryckstyrd med bättre effektivitet | L28: ='Byte av fläkt'!B2 -> Nej | M28: =IFERROR(IF('Byte av fläkt'!B2="Ja",'Byte av fläkt'!D20,""),"") | N28: =IFERROR(IF('Byte av fläkt'!B2="Ja",'Byte av fläkt'!C35-'Byte av fläkt'!D35,""),"") | O28: =IFERROR(IF('Byte av fläkt'!B2="Ja",'Byte av fläkt'!C34-'Byte av fläkt'!D34,""),"") | P28: =IFERROR(IF('Byte av fläkt'!B2="Ja",'Byte av fläkt'!E6,""),"") | Q28: =IFERROR(IF('Byte av fläkt'!B2="Ja",'Byte av fläkt'!D43,""),"") | R28: =IF(L28="Ja",IF(AND(ISNUMBER(P28),N(P28)>=0),P28,1000000),2000000)+ROW()/1000000 -> 2000000
A29: =IFERROR(IF(INDEX($K$19:$K$29,MATCH(SMALL($R$19:$R$29,11),$R$19:$R$29,0))="","",INDEX($K$19:$K$29,MATCH(SMALL($R$19:$R$29,11),$R$19:$R$29,0))),"") -> Övrig åtgärd | B29: =IFERROR(IF(INDEX($L$19:$L$29,MATCH(SMALL($R$19:$R$29,11),$R$19:$R$29,0))="","",INDEX($L$19:$L$29,MATCH(SMALL($R$19:$R$29,11),$R$19:$R$29,0))),"") -> Nej | C29: =IFERROR(IF(INDEX($M$19:$M$29,MATCH(SMALL($R$19:$R$29,11),$R$19:$R$29,0))="","",INDEX($M$19:$M$29,MATCH(SMALL($R$19:$R$29,11),$R$19:$R$29,0))),"") | D29: =IFERROR(IF(INDEX($N$19:$N$29,MATCH(SMALL($R$19:$R$29,11),$R$19:$R$29,0))="","",INDEX($N$19:$N$29,MATCH(SMALL($R$19:$R$29,11),$R$19:$R$29,0))),"") | E29: =IFERROR(IF(INDEX($O$19:$O$29,MATCH(SMALL($R$19:$R$29,11),$R$19:$R$29,0))="","",INDEX($O$19:$O$29,MATCH(SMALL($R$19:$R$29,11),$R$19:$R$29,0))),"") | F29: =IFERROR(IF(INDEX($P$19:$P$29,MATCH(SMALL($R$19:$R$29,11),$R$19:$R$29,0))="","",INDEX($P$19:$P$29,MATCH(SMALL($R$19:$R$29,11),$R$19:$R$29,0))),"") | G29: =IFERROR(IF(INDEX($Q$19:$Q$29,MATCH(SMALL($R$19:$R$29,11),$R$19:$R$29,0))="","",INDEX($Q$19:$Q$29,MATCH(SMALL($R$19:$R$29,11),$R$19:$R$29,0))),"") | K29: ='Övrig åtgärd'!A1 -> Övrig åtgärd | L29: ='Övrig åtgärd'!B2 -> Nej | M29: =IFERROR(IF('Övrig åtgärd'!B2="Ja",'Övrig åtgärd'!D20,""),"") | N29: =IFERROR(IF('Övrig åtgärd'!B2="Ja",'Övrig åtgärd'!C35-'Övrig åtgärd'!D35,""),"") | O29: =IFERROR(IF('Övrig åtgärd'!B2="Ja",'Övrig åtgärd'!C34-'Övrig åtgärd'!D34,""),"") | P29: =IFERROR(IF('Övrig åtgärd'!B2="Ja",'Övrig åtgärd'!E6,""),"") | Q29: =IFERROR(IF('Övrig åtgärd'!B2="Ja",'Övrig åtgärd'!D43,""),"") | R29: =IF(L29="Ja",IF(AND(ISNUMBER(P29),N(P29)>=0),P29,1000000),2000000)+ROW()/1000000 -> 2000000
A30: Summa aktiverade åtgärder | C30: =SUM(C19:C29) -> 0 | D30: =SUM(D19:D29) -> 0 | E30: =SUM(E19:E29) -> 0

Sheet Byggnader
A1: Byggnader och A-temp
A2: En kolumn per fysisk byggnad, varje byggnad blir en egen energideklaration i Gripen. Lämna oanvända kolumner tomma.
A4: Fastighet
A5: Fastighetsbeteckning
A6: Kommun | C6: Karlstad
A7: Geografisk justeringsfaktor Fgeo | C7: =IFERROR(INDEX('Regler BFS 2026'!$B$30:$B$319,MATCH(C6,'Regler BFS 2026'!$A$30:$A$319,0)),"Välj kommun") -> 1
A8: Mätperiod från och med (ÅÅMM)
A9: Mätperiod till och med (ÅÅMM)
A10: Energiindex för mätperioden (endast kontroll av Etal) | C10: 1
A12: Byggnad | C12: Byggnad 1 | D12: Byggnad 2 | E12: Byggnad 3 | F12: Byggnad 4 | G12: Byggnad 5 | H12: Byggnad 6 | I12: Summa
A13: Egen beteckning
A14: Adress
A15: Husnummer / byggnads-ID
A16: Byggnadstyp (bostadsdel) | C16: Flerbostadshus | D16: Flerbostadshus | E16: Flerbostadshus | F16: Flerbostadshus | G16: Flerbostadshus | H16: Flerbostadshus
A17: Nybyggnadsår
A18: Antal lägenheter | I18: =SUM(C18:H18) -> 0
A20: A-temp per byggnad (m²)
A21: A-temp bostäder inkl. biarea | I21: =SUM(C21:H21) -> 0
A23: A-temp lokaler per kategori enligt BFS 2026:9 (m²)
A24: Kontor | I24: =SUM(C24:H24) -> 0
A25: Utbildning | I25: =SUM(C25:H25) -> 0
A26: Sjukhus | I26: =SUM(C26:H26) -> 0
A27: Logi och restaurang | I27: =SUM(C27:H27) -> 0
A28: Idrott | I28: =SUM(C28:H28) -> 0
A29: Handel och kultur | I29: =SUM(C29:H29) -> 0
A30: Annan typ av energianvändande byggnad | I30: =SUM(C30:H30) -> 0
A31: Varmgarage (m²) | I31: =SUM(C31:H31) -> 0
A32: A-temp totalt (m²) | C32: =C21+SUM(C24:C31) -> 0 | D32: =D21+SUM(D24:D31) -> 0 | E32: =E21+SUM(E24:E31) -> 0 | F32: =F21+SUM(F24:F31) -> 0 | G32: =G21+SUM(G24:G31) -> 0 | H32: =H21+SUM(H24:H31) -> 0 | I32: =I21+SUM(I24:I31) -> 0
A33: Andel av fastighetens A-temp | C33: =IFERROR(C32/$I$32,0) -> 0 | D33: =IFERROR(D32/$I$32,0) -> 0 | E33: =IFERROR(E32/$I$32,0) -> 0 | F33: =IFERROR(F32/$I$32,0) -> 0 | G33: =IFERROR(G32/$I$32,0) -> 0 | H33: =IFERROR(H32/$I$32,0) -> 0 | I33: =IFERROR(I32/$I$32,0) -> 0
A35: Fördelning av gemensamma mätare
A36: Används för mätare som försörjer "Alla" byggnader, t.ex. en fjärrvärmecentral med kulvert. Manuell andel ersätter den automatiska.
A37: Uppvärmning, automatisk andel (A-temp) | C37: =IFERROR(C32/$I$32,0) -> 0 | D37: =IFERROR(D32/$I$32,0) -> 0 | E37: =IFERROR(E32/$I$32,0) -> 0 | F37: =IFERROR(F32/$I$32,0) -> 0 | G37: =IFERROR(G32/$I$32,0) -> 0 | H37: =IFERROR(H32/$I$32,0) -> 0 | I37: =SUM(C37:H37) -> 0
A38: Uppvärmning, manuell andel | I38: =SUM(C38:H38) -> 0
A39: Uppvärmning, använd andel | C39: =IF(C38="",C37,C38) -> 0 | D39: =IF(D38="",D37,D38) -> 0 | E39: =IF(E38="",E37,E38) -> 0 | F39: =IF(F38="",F37,F38) -> 0 | G39: =IF(G38="",G37,G38) -> 0 | H39: =IF(H38="",H37,H38) -> 0 | I39: =SUM(C39:H39) -> 0
A40: Tappvarmvatten, automatisk andel (lägenheter, annars A-temp) | C40: =IF($I$18>0,IFERROR(C18/$I$18,0),IFERROR(C32/$I$32,0)) -> 0 | D40: =IF($I$18>0,IFERROR(D18/$I$18,0),IFERROR(D32/$I$32,0)) -> 0 | E40: =IF($I$18>0,IFERROR(E18/$I$18,0),IFERROR(E32/$I$32,0)) -> 0 | F40: =IF($I$18>0,IFERROR(F18/$I$18,0),IFERROR(F32/$I$32,0)) -> 0 | G40: =IF($I$18>0,IFERROR(G18/$I$18,0),IFERROR(G32/$I$32,0)) -> 0 | H40: =IF($I$18>0,IFERROR(H18/$I$18,0),IFERROR(H32/$I$32,0)) -> 0 | I40: =SUM(C40:H40) -> 0
A41: Tappvarmvatten, manuell andel | I41: =SUM(C41:H41) -> 0
A42: Tappvarmvatten, använd andel | C42: =IF(C41="",C40,C41) -> 0 | D42: =IF(D41="",D40,D41) -> 0 | E42: =IF(E41="",E40,E41) -> 0 | F42: =IF(F41="",F40,F41) -> 0 | G42: =IF(G41="",G40,G41) -> 0 | H42: =IF(H41="",H40,H41) -> 0 | I42: =SUM(C42:H42) -> 0
A43: El, kyla och övrigt (A-temp) | C43: =IFERROR(C32/$I$32,0) -> 0 | D43: =IFERROR(D32/$I$32,0) -> 0 | E43: =IFERROR(E32/$I$32,0) -> 0 | F43: =IFERROR(F32/$I$32,0) -> 0 | G43: =IFERROR(G32/$I$32,0) -> 0 | H43: =IFERROR(H32/$I$32,0) -> 0 | I43: =SUM(C43:H43) -> 0
A44: Hushållsel (A-temp bostäder) | C44: =IF($I$21>0,IFERROR(C21/$I$21,0),C43) -> 0 | D44: =IF($I$21>0,IFERROR(D21/$I$21,0),D43) -> 0 | E44: =IF($I$21>0,IFERROR(E21/$I$21,0),E43) -> 0 | F44: =IF($I$21>0,IFERROR(F21/$I$21,0),F43) -> 0 | G44: =IF($I$21>0,IFERROR(G21/$I$21,0),G43) -> 0 | H44: =IF($I$21>0,IFERROR(H21/$I$21,0),H43) -> 0 | I44: =SUM(C44:H44) -> 0
A46: Egenanvänd solel som minskar energiprestandatalet (från fliken Solceller)
...

Sheet Tidigare deklarationer
A1: Tidigare energideklarationer
A2: Uppgifter inlästa från tidigare energideklarationer. Används som referens och av Gripen-exporten. Energivärdena gäller den tidigare mätperioden.
A4: Byggnad | C4: =Byggnader!C12 -> Byggnad 1 | D4: =Byggnader!D12 -> Byggnad 2 | E4: =Byggnader!E12 -> Byggnad 3 | F4: =Byggnader!F12 -> Byggnad 4 | G4: =Byggnader!G12 -> Byggnad 5 | H4: =Byggnader!H12 -> Byggnad 6
A5: Energideklarations-ID
A6: Blankettversion
A7: Datum för godkännande
A8: Län
A9: Kommun
A10: Fastighetsbeteckning
A11: Egen beteckning
A12: Husnummer
A13: Prefix byggnadsid
A14: Byggnadsid
A15: Adresser (adress; postnr; postort | …)
A16: Typkod
... A51: Inläsningskommentarer

Sheet Mätdata
A1: Köpt energi och vatten
A2: Ange uppmätt energi för mätperioden, ej normalårskorrigerad. Välj vilken byggnad mätaren försörjer, eller Alla om den är gemensam.
A4: Energimätare
A5: Mätare / benämning | B5: Energibärare | C5: Ändamål | D5: Försörjer | E5: kWh | F5: Kommentar
J7: Effekt | K7: YTA | L7: Årsprod
H8: Solceller | I8: HUS1 15A | J8: 13.4 | K8: =44*1.8 -> 79.2 | L8: =160*K8 -> 12672
I9: HUS2 4 | J9: 13.4 | K9: =44*1.8 -> 79.2 | L9: =160*K9 -> 12672
I12: Förbruklning enligt Ellevio | L12: HUS A | M12: 27117
L13: HUS B | M13: 28841
I14: Produktion enligt Ellevio | L14: HUS A | M14: 3831
L15: HUS B | M15: 4381
I18: Husens elförbukning | M18: =E7+E8+E9+E10 -> 0
I19: Varav hushållsel | M19: =E7+E8 -> 0
I20: Varav fastighets el | M20: =Besiktningsprotokoll!D125 -> 12193.8
I21: Varav veksamhetsel | M21: =Besiktningsprotokoll!D146 -> 0
A26: Solceller och såld el anges i fliken Solceller, inte som mätare här.
A27: Vattenmätare
A28: Mätare / benämning | B28: Försörjer | C28: m³
A37: Summa vatten (m³) | C37: =SUM(C29:C36) -> 0
A39: Tappvarmvatten
A40: Andel varmvatten av total vattenförbrukning | B40: 0.35
A41: Energiinnehåll i varmvatten (kWh/m³) | B41: 55
A42: Verkningsgrad varmvattensystem inkl. VVC | B42: 1
A43: Faktiskt energibehov om vattenmätning saknas (kWh/m²,år) | B43: 25
A45: Värmeproduktion
A46: Värmekälla | B46: Köpt energi kWh/år | C46: Andel av varmvattenproduktion | D46: Årsverkningsgrad | E46: Viktningsfaktor | F46: Energikälla i Gripen
A47: Fjärrvärme | B47: =SUMIFS($E$6:$E$25,$B$6:$B$25,"Fjärrvärme",$C$6:$C$25,"Värme och tappvarmvatten") -> 0 | C47: 1 | D47: 1 | E47: ='Regler BFS 2026'!$B$5 -> 0.7 | F47: Fjärrvärme
A48: Värmepump (el) | B48: =SUMIFS($E$6:$E$25,$B$6:$B$25,"El",$C$6:$C$25,"Värmepump")+C62 -> 0 | C48: 0 | D48: 2.5 | E48: ='Regler BFS 2026'!$B$4 -> 1.8 | F48: Värmepump – välj typ
A49: Elvärme | B49: =SUMIFS($E$6:$E$25,$B$6:$B$25,"El",$C$6:$C$25,"Elvärme")+C63 -> 0 | C49: 0 | D49: 1 | E49: ='Regler BFS 2026'!$B$4 -> 1.8 | F49: El – välj typ
A50: Olja | B50: =SUMIFS($E$6:$E$25,$B$6:$B$25,"Olja",$C$6:$C$25,"Värme och tappvarmvatten") -> 0 | C50: 0 | D50: 0.85 | E50: ='Regler BFS 2026'!$B$8 -> 1.8 | F50: Olja
A51: Gas | B51: =SUMIFS($E$6:$E$25,$B$6:$B$25,"Gas",$C$6:$C$25,"Värme och tappvarmvatten") -> 0 | C51: 0 | D51: 0.9 | E51: ='Regler BFS 2026'!$B$8 -> 1.8 | F51: Gas
A52: Pellets/flis/briketter | B52: =SUMIFS($E$6:$E$25,$B$6:$B$25,"Pellets/flis/briketter",$C$6:$C$25,"Värme och tappvarmvatten") -> 0 | C52: 0 | D52: 0.85 | E52: ='Regler BFS 2026'!$B$7 -> 0.6 | F52: Flis/pellets/briketter
A53: Ved | B53: =SUMIFS($E$6:$E$25,$B$6:$B$25,"Ved",$C$6:$C$25,"Värme och tappvarmvatten") -> 0 | C53: 0 | D53: 0.75 | E53: ='Regler BFS 2026'!$B$7 -> 0.6 | F53: Ved
A54: Övrigt biobränsle | B54: =SUMIFS($E$6:$E$25,$B$6:$B$25,"Övrigt biobränsle",$C$6:$C$25,"Värme och tappvarmvatten") -> 0 | C54: 0 | D54: 0.85 | E54: ='Regler BFS 2026'!$B$7 -> 0.6 | F54: Övrigt biobränsle
A55: Summa | B55: =SUM(B47:B54) -> 0 | C55: =SUM(C47:C54) -> 1
A56: Kulvertförluster (kWh/år) | B56: 0
A57: Kulvertförluster hanteras | B57: Fördelas på byggnaderna
A59: Fördelning av el
A60: Ändamål | B60: Egen mätare kWh | C60: Enligt besiktning om egen mätare saknas, kWh | D60: Totalt kWh
A61: Fastighetselen har ingen egen mätare. Den hämtas från besiktningsprotokollets sammanställning (rad 68).
...

Sheet Solceller
A1: Solceller och egenanvänd solel
A2: Egenanvänd solel fördelas på förbrukarna efter årsförbrukning × samtidighetsfaktor. Bara delen till fastighetsel, värmepump, elvärme och komfortkyla minskar energiprestandatalet (BFS 2026:9 1 kap. 8 §).
A4: Gemensamt för fastigheten
A5: Specifik produktion (kWh/kWp,år) | C5: 900
A6: Uppmätt total produktion, om produktion per byggnad saknas (kWh/år)
A7: Såld el, gemensam exportmätare (kWh/år)
A8: Egenanvänd solel fördelas | C8: Gemensamt för fastigheten
A10: Produktion per byggnad
A11: Byggnad | C11: =Byggnader!C12 -> Byggnad 1 | D11: =Byggnader!D12 -> Byggnad 2 | E11: =Byggnader!E12 -> Byggnad 3 | F11: =Byggnader!F12 -> Byggnad 4 | G11: =Byggnader!G12 -> Byggnad 5 | H11: =Byggnader!H12 -> Byggnad 6 | I11: Summa
A12: Egen beteckning | C12: =IF(Byggnader!C13="","",Byggnader!C13) | D12: =IF(Byggnader!D13="","",Byggnader!D13) | E12: =IF(Byggnader!E13="","",Byggnader!E13) | F12: =IF(Byggnader!F13="","",Byggnader!F13) | G12: =IF(Byggnader!G13="","",Byggnader!G13) | H12: =IF(Byggnader!H13="","",Byggnader!H13)
A13: Installerad effekt (kWp) | I13: =SUM(C13:H13) -> 0
A14: Uppmätt produktion per byggnad (kWh/år) | I14: =SUM(C14:H14) -> 0
A15: Såld el per byggnad (kWh/år) | I15: =SUM(C15:H15) -> 0
A16: Produktion (kWh/år) | C16: =IF(C14<>"",C14,IF($C$6>0,$C$6*IF($I$13>0,C13/$I$13,Byggnader!C33),C13*$C$5)) -> 0 | D16: =IF(D14<>"",D14,IF($C$6>0,$C$6*IF($I$13>0,D13/$I$13,Byggnader!D33),D13*$C$5)) -> 0 | E16: =IF(E14<>"",E14,IF($C$6>0,$C$6*IF($I$13>0,E13/$I$13,Byggnader!E33),E13*$C$5)) -> 0 | F16: =IF(F14<>"",F14,IF($C$6>0,$C$6*IF($I$13>0,F13/$I$13,Byggnader!F33),F13*$C$5)) -> 0 | G16: =IF(G14<>"",G14,IF($C$6>0,$C$6*IF($I$13>0,G13/$I$13,Byggnader!G33),G13*$C$5)) -> 0 | H16: =IF(H14<>"",H14,IF($C$6>0,$C$6*IF($I$13>0,H13/$I$13,Byggnader!H33),H13*$C$5)) -> 0 | I16: =SUM(C16:H16) -> 0
A17: Såld el (kWh/år) | C17: =N(C15)+$C$7*IFERROR(C16/$I$16,0) -> 0 | D17: =N(D15)+$C$7*IFERROR(D16/$I$16,0) -> 0 | E17: =N(E15)+$C$7*IFERROR(E16/$I$16,0) -> 0 | F17: =N(F15)+$C$7*IFERROR(F16/$I$16,0) -> 0 | G17: =N(G15)+$C$7*IFERROR(G16/$I$16,0) -> 0 | H17: =N(H15)+$C$7*IFERROR(H16/$I$16,0) -> 0 | I17: =SUM(C17:H17) -> 0
A18: Egenanvänd solel, egen produktion (kWh/år) | C18: =MAX(0,C16-C17) -> 0 | D18: =MAX(0,D16-D17) -> 0 | E18: =MAX(0,E16-E17) -> 0 | F18: =MAX(0,F16-F17) -> 0 | G18: =MAX(0,G16-G17) -> 0 | H18: =MAX(0,H16-H17) -> 0 | I18: =SUM(C18:H18) -> 0
A20: Elanvändning som kan täckas av solel (kWh/år)
A21: Byggnad | B21: Samtidighets-faktor | C21: =Byggnader!C12 -> Byggnad 1 | D21: =Byggnader!D12 -> Byggnad 2 | E21: =Byggnader!E12 -> Byggnad 3 | F21: =Byggnader!F12 -> Byggnad 4 | G21: =Byggnader!G12 -> Byggnad 5 | H21: =Byggnader!H12 -> Byggnad 6 | I21: Summa
A22: Hushållsel | B22: 1 | C22: =Normalisering!C143 -> 0 | D22: =Normalisering!D143 -> 0 | E22: =Normalisering!E143 -> 0 | F22: =Normalisering!F143 -> 0 | G22: =Normalisering!G143 -> 0 | H22: =Normalisering!H143 -> 0 | I22: =SUM(C22:H22) -> 0
A23: Verksamhetsel | B23: 1 | C23: =Normalisering!C144 -> 0 | D23: =Normalisering!D144 -> 0 | E23: =Normalisering!E144 -> 0 | F23: =Normalisering!F144 -> 0 | G23: =Normalisering!G144 -> 0 | H23: =Normalisering!H144 -> 0 | I23: =SUM(C23:H23) -> 0
A24: El utanför systemgräns (hiss m.m.) | B24: 1 | C24: =Normalisering!C145 -> 0 | D24: =Normalisering!D145 -> 0 | E24: =Normalisering!E145 -> 0 | F24: =Normalisering!F145 -> 0 | G24: =Normalisering!G145 -> 0 | H24: =Normalisering!H145 -> 0 | I24: =SUM(C24:H24) -> 0
A25: Fastighetsel inom systemgräns | B25: 1 | C25: =Normalisering!C137 -> 0 | D25: =Normalisering!D137 -> 0 | E25: =Normalisering!E137 -> 0 | F25: =Normalisering!F137 -> 0 | G25: =Normalisering!G137 -> 0 | H25: =Normalisering!H137 -> 0 | I25: =SUM(C25:H25) -> 0
A26: Värmepump | B26: 1 | C26: =Normalisering!C58 -> 0 | D26: =Normalisering!D58 -> 0 | E26: =Normalisering!E58 -> 0 | F26: =Normalisering!F58 -> 0 | G26: =Normalisering!G58 -> 0 | H26: =Normalisering!H58 -> 0 | I26: =SUM(C26:H26) -> 0
A27: Elvärme och el för komfortkyla | B27: 1 | C27: =Normalisering!C59+Normalisering!C140 -> 0 | D27: =Normalisering!D59+Normalisering!D140 -> 0 | E27: =Normalisering!E59+Normalisering!E140 -> 0 | F27: =Normalisering!F59+Normalisering!F140 -> 0 | G27: =Normalisering!G59+Normalisering!G140 -> 0 | H27: =Normalisering!H59+Normalisering!H140 -> 0 | I27: =SUM(C27:H27) -> 0
A28: Summa förbrukning | C28: =SUM(C22:C27) -> 0 | D28: =SUM(D22:D27) -> 0 | E28: =SUM(E22:E27) -> 0 | F28: =SUM(F22:F27) -> 0 | G28: =SUM(G22:G27) -> 0 | H28: =SUM(H22:H27) -> 0 | I28: =SUM(I22:I27) -> 0
A29: Summa förbrukning × samtidighetsfaktor | C29: =SUMPRODUCT($B$22:$B$27,C22:C27) -> 0 | D29: =SUMPRODUCT($B$22:$B$27,D22:D27) -> 0 | E29: =SUMPRODUCT($B$22:$B$27,E22:E27) -> 0 | F29: =SUMPRODUCT($B$22:$B$27,F22:F27) -> 0 | G29: =SUMPRODUCT($B$22:$B$27,G22:G27) -> 0 | H29: =SUMPRODUCT($B$22:$B$27,H22:H27) -> 0 | I29: =SUMPRODUCT($B$22:$B$27,I22:I27) -> 0
A30: Egenanvänd solel att fördela (kWh/år) | C30: =MIN(C28,IF($C$8="Gemensamt för fastigheten",$I$18*IFERROR(C29/$I$29,0),C18)) -> 0 | D30: =MIN(D28,IF($C$8="Gemensamt för fastigheten",$I$18*IFERROR(D29/$I$29,0),D18)) -> 0 | E30: =MIN(E28,IF($C$8="Gemensamt för fastigheten",$I$18*IFERROR(E29/$I$29,0),E18)) -> 0 | F30: =MIN(F28,IF($C$8="Gemensamt för fastigheten",$I$18*IFERROR(F29/$I$29,0),F18)) -> 0 | G30: =MIN(G28,IF($C$8="Gemensamt för fastigheten",$I$18*IFERROR(G29/$I$29,0),G18)) -> 0 | H30: =MIN(H28,IF($C$8="Gemensamt för fastigheten",$I$18*IFERROR(H29/$I$29,0),H18)) -> 0 | I30: =SUM(C30:H30) -> 0
A32: Fördelning av egenanvänd solel (kWh/år)
A33: Byggnad | C33: =Byggnader!C12 -> Byggnad 1 | D33: =Byggnader!D12 -> Byggnad 2 | E33: =Byggnader!E12 -> Byggnad 3 | F33: =Byggnader!F12 -> Byggnad 4 | G33: =Byggnader!G12 -> Byggnad 5 | H33: =Byggnader!H12 -> Byggnad 6 | I33: Summa
A34: Hushållsel | C34: =IFERROR(MIN(C22,C$30*$B22*C22/C$29),0) -> 0 | D34: =IFERROR(MIN(D22,D$30*$B22*D22/D$29),0) -> 0 | E34: =IFERROR(MIN(E22,E$30*$B22*E22/E$29),0) -> 0 | F34: =IFERROR(MIN(F22,F$30*$B22*F22/F$29),0) -> 0 | G34: =IFERROR(MIN(G22,G$30*$B22*G22/G$29),0) -> 0 | H34: =IFERROR(MIN(H22,H$30*$B22*H22/H$29),0) -> 0 | I34: =SUM(C34:H34) -> 0
A35: Verksamhetsel | C35: =IFERROR(MIN(C23,C$30*$B23*C23/C$29),0) -> 0 | D35: =IFERROR(MIN(D23,D$30*$B23*D23/D$29),0) -> 0 | E35: =IFERROR(MIN(E23,E$30*$B23*E23/E$29),0) -> 0 | F35: =IFERROR(MIN(F23,F$30*$B23*F23/F$29),0) -> 0 | G35: =IFERROR(MIN(G23,G$30*$B23*G23/G$29),0) -> 0 | H35: =IFERROR(MIN(H23,H$30*$B23*H23/H$29),0) -> 0 | I35: =SUM(C35:H35) -> 0
A36: El utanför systemgräns (hiss m.m.) | C36: =IFERROR(MIN(C24,C$30*$B24*C24/C$29),0) -> 0 | D36: =IFERROR(MIN(D24,D$30*$B24*D24/D$29),0) -> 0 | E36: =IFERROR(MIN(E24,E$30*$B24*E24/E$29),0) -> 0 | F36: =IFERROR(MIN(F24,F$30*$B24*F24/F$29),0) -> 0 | G36: =IFERROR(MIN(G24,G$30*$B24*G24/G$29),0) -> 0 | H36: =IFERROR(MIN(H24,H$30*$B24*H24/H$29),0) -> 0 | I36: =SUM(C36:H36) -> 0
A37: Fastighetsel inom systemgräns | C37: =IFERROR(MIN(C25,C$30*$B25*C25/C$29),0) -> 0 | D37: =IFERROR(MIN(D25,D$30*$B25*D25/D$29),0) -> 0 | E37: =IFERROR(MIN(E25,E$30*$B25*E25/E$29),0) -> 0 | F37: =IFERROR(MIN(F25,F$30*$B25*F25/F$29),0) -> 0 | G37: =IFERROR(MIN(G25,G$30*$B25*G25/G$29),0) -> 0 | H37: =IFERROR(MIN(H25,H$30*$B25*H25/H$29),0) -> 0 | I37: =SUM(C37:H37) -> 0
A38: Värmepump | C38: =IFERROR(MIN(C26,C$30*$B26*C26/C$29),0) -> 0 | D38: =IFERROR(MIN(D26,D$30*$B26*D26/D$29),0) -> 0 | E38: =IFERROR(MIN(E26,E$30*$B26*E26/E$29),0) -> 0 | F38: =IFERROR(MIN(F26,F$30*$B26*F26/F$29),0) -> 0 | G38: =IFERROR(MIN(G26,G$30*$B26*G26/G$29),0) -> 0 | H38: =IFERROR(MIN(H26,H$30*$B26*H26/H$29),0) -> 0 | I38: =SUM(C38:H38) -> 0
A39: Elvärme och el för komfortkyla | C39: =IFERROR(MIN(C27,C$30*$B27*C27/C$29),0) -> 0 | D39: =IFERROR(MIN(D27,D$30*$B27*D27/D$29),0) -> 0 | E39: =IFERROR(MIN(E27,E$30*$B27*E27/E$29),0) -> 0 | F39: =IFERROR(MIN(F27,F$30*$B27*F27/F$29),0) -> 0 | G39: =IFERROR(MIN(G27,G$30*$B27*G27/G$29),0) -> 0 | H39: =IFERROR(MIN(H27,H$30*$B27*H27/H$29),0) -> 0 | I39: =SUM(C39:H39) -> 0
A40: Summa fördelad | C40: =SUM(C34:C39) -> 0 | D40: =SUM(D34:D39) -> 0 | E40: =SUM(E34:E39) -> 0 | F40: =SUM(F34:F39) -> 0 | G40: =SUM(G34:G39) -> 0 | H40: =SUM(H34:H39) -> 0 | I40: =SUM(I34:I39) -> 0
A42: Solel som minskar energiprestandatalet (kWh/år)
A43: Byggnad | C43: =Byggnader!C12 -> Byggnad 1 | D43: =Byggnader!D12 -> Byggnad 2 | E43: =Byggnader!E12 -> Byggnad 3 | F43: =Byggnader!F12 -> Byggnad 4 | G43: =Byggnader!G12 -> Byggnad 5 | H43: =Byggnader!H12 -> Byggnad 6 | I43: Summa
A44: Till fastighetsenergi | C44: =C37 -> 0 | D44: =D37 -> 0 | E44: =E37 -> 0 | F44: =F37 -> 0 | G44: =G37 -> 0 | H44: =H37 -> 0 | I44: =I37 -> 0
A45: Till värmepump, elvärme och komfortkyla | C45: =C38+C39 -> 0 | D45: =D38+D39 -> 0 | E45: =E38+E39 -> 0 | F45: =F38+F39 -> 0 | G45: =G38+G39 -> 0 | H45: =H38+H39 -> 0 | I45: =I38+I39 -> 0
...

Sheet Besiktningsprotokoll
A1: Besiktningsprotokoll energideklaration
A2: Indata
A3: Kund | C3: Utförare | D3: Peter Persson
A4: Byggnad | C4: Företag | D4: HSB Värmland
A5: Adress | C5: Telefon | D5: 0708-192035
A6: Uppmätt yta A-temp m2 | B6: =Byggnader!I32 -> 0 | C6: Mail | D6: peter.persson@hsb.se
A7: Energi enligt besiktning | B7: Elvärme | C7: Fastighetsel (Belysning, elmotorer mm. | E7: Beräknat värde av övrig el (Tvättstugor, motorvärmare utebelysning)
B8: =D130 -> 0 | C8: =D125 -> 12193.8 | E8: =D146+D107 -> 0
B9: El värmepump | C9: El komfortkyla | E9: Övrigt
B10: =G88 -> 0 | C10: =J88 -> 0
A11: 1 Klimatskärm
B12: Klimatskärm
B13: U-värde | E13: Kommentar
A14: Ytterväggar 1
A15: Ytterväggar källare
A16: Takbjälklag
A17: Fönster
A18: Övrigt
A19: 2 Klimat
B20: Klimat
B21: Mätningar | E21: Kommentar
A22: Rumstemperatur
A23: Rumstemperatur | B23: 21-22 | E23: Bedömt
A24: Rumstemperatur
A25: 3 Värmeproduktion/Inspektionsprotokoll | G25: Beräkning effekt via fjärrvärme
A26: Värmeproduktion beskrivning | G26: Utetemp | H26: -20
A27: Nominell effekt kW | B27: =Mätdata!E6/2000 -> 0 | G27: Faktor 1 | H27: -1.7
A28: Effekt W/m2 | B28: =B27*1000/(Byggnader!C17+Byggnader!D17) -> #DIV/0! | G28: Faktor 2 | H28: 29.39
A29: Bedömningsgrund | G29: VV% | H29: 0
A30: Kommentar | G30: Effekt tot | H30: =(H27*H26+H28)-(H27*H26+H28)*H29 -> 63.39
A31: 4 Värmedistribution/Inspektionsprotokoll
E32: Kommentar
A33: Tryckuppsättning pump Mvp
A34: Stamventiler
A35: Radiatorventiler
A36: Termostater
A37: Rörsystem/Radiatorer
A38: Isolering
A39: Injustering bedömning
A40: Dimensionering
...

Sheet Bilder
K202: 2022
G428: 7W
B581: Vindsisolering 2016

Sheet Normalisering
A1: Fördelning och normalisering per byggnad
A2: Uppvärmningen normaliseras till kategoritypisk användning men inte till normalår. Klimatkorrigeringen görs i Gripen.
A4: Schabloner
A5: Korrigering per grad avvikande innetemperatur (andel) | B5: 0.05
A6: Andel av el som blir tillgodogjord värme | B6: 0.7
A7: Personvärme per person (W) | B7: 80
A8: Närvarotid (h/dygn) | B8: 14
A9: Timmar uppvärmningssäsong (h) | B9: 6000
A10: Gradtimmar för ventilationsberäkning (°Ch) | B10: 100000
A12: Faktisk användning och val per byggnad
A13: Byggnad | C13: =Byggnader!C12 -> Byggnad 1 | D13: =Byggnader!D12 -> Byggnad 2 | E13: =Byggnader!E12 -> Byggnad 3 | F13: =Byggnader!F12 -> Byggnad 4 | G13: =Byggnader!G12 -> Byggnad 5 | H13: =Byggnader!H12 -> Byggnad 6 | I13: Summa
A14: Faktisk innetemperatur (°C) | C14: 21 | D14: 21 | E14: 21 | F14: 21 | G14: 21 | H14: 21
A15: Faktiskt uteluftsflöde (l/s,m²) | C15: 0.35 | D15: 0.35 | E15: 0.35 | F15: 0.35 | G15: 0.35 | H15: 0.35
A16: Värmeåtervinning ventilation (årsverkningsgrad) | C16: 0 | D16: 0 | E16: 0 | F16: 0 | G16: 0 | H16: 0
A17: Personer per lägenhet | C17: 1.63 | D17: 1.63 | E17: 1.63 | F17: 1.63 | G17: 1.63 | H17: 1.63
A18: Verksamhetsel inomhus som avger värme (kWh/år) | C18: 0 | D18: 0 | E18: 0 | F18: 0 | G18: 0 | H18: 0
A19: Normalisering innetemperatur (Ja/Nej) | C19: Ja | D19: Ja | E19: Ja | F19: Ja | G19: Ja | H19: Ja
A20: Normalisering uteluftsflöde (Ja/Nej) | C20: Ja | D20: Ja | E20: Ja | F20: Ja | G20: Ja | H20: Ja
A21: Normalisering internlast (Ja/Nej) | C21: Ja | D21: Ja | E21: Ja | F21: Ja | G21: Ja | H21: Ja
A22: Normalisering tappvarmvatten (Ja/Nej) | C22: Ja | D22: Ja | E22: Ja | F22: Ja | G22: Ja | H22: Ja
A24: Areor och kategoritypiska värden
A25: Byggnad | C25: =Byggnader!C12 -> Byggnad 1 | D25: =Byggnader!D12 -> Byggnad 2 | E25: =Byggnader!E12 -> Byggnad 3 | F25: =Byggnader!F12 -> Byggnad 4 | G25: =Byggnader!G12 -> Byggnad 5 | H25: =Byggnader!H12 -> Byggnad 6 | I25: Summa
A26: A-temp (m²) | C26: =Byggnader!C32 -> 0 | D26: =Byggnader!D32 -> 0 | E26: =Byggnader!E32 -> 0 | F26: =Byggnader!F32 -> 0 | G26: =Byggnader!G32 -> 0 | H26: =Byggnader!H32 -> 0 | I26: =SUM(C26:H26) -> 0
A27: Flerbostadshus | C27: =IF(Byggnader!C16="Flerbostadshus",(Byggnader!C21+Byggnader!C31),0) -> 0 | D27: =IF(Byggnader!D16="Flerbostadshus",(Byggnader!D21+Byggnader!D31),0) -> 0 | E27: =IF(Byggnader!E16="Flerbostadshus",(Byggnader!E21+Byggnader!E31),0) -> 0 | F27: =IF(Byggnader!F16="Flerbostadshus",(Byggnader!F21+Byggnader!F31),0) -> 0 | G27: =IF(Byggnader!G16="Flerbostadshus",(Byggnader!G21+Byggnader!G31),0) -> 0 | H27: =IF(Byggnader!H16="Flerbostadshus",(Byggnader!H21+Byggnader!H31),0) -> 0 | I27: =SUM(C27:H27) -> 0
A28: En- och tvåbostadshus < 90 m² | C28: =IF(AND(Byggnader!C16="En- och tvåbostadshus",C26<90),(Byggnader!C21+Byggnader!C31),0) -> 0 | D28: =IF(AND(Byggnader!D16="En- och tvåbostadshus",D26<90),(Byggnader!D21+Byggnader!D31),0) -> 0 | E28: =IF(AND(Byggnader!E16="En- och tvåbostadshus",E26<90),(Byggnader!E21+Byggnader!E31),0) -> 0 | F28: =IF(AND(Byggnader!F16="En- och tvåbostadshus",F26<90),(Byggnader!F21+Byggnader!F31),0) -> 0 | G28: =IF(AND(Byggnader!G16="En- och tvåbostadshus",G26<90),(Byggnader!G21+Byggnader!G31),0) -> 0 | H28: =IF(AND(Byggnader!H16="En- och tvåbostadshus",H26<90),(Byggnader!H21+Byggnader!H31),0) -> 0 | I28: =SUM(C28:H28) -> 0
A29: En- och tvåbostadshus 90–130 m² | C29: =IF(AND(Byggnader!C16="En- och tvåbostadshus",C26>=90,C26<130),(Byggnader!C21+Byggnader!C31),0) -> 0 | D29: =IF(AND(Byggnader!D16="En- och tvåbostadshus",D26>=90,D26<130),(Byggnader!D21+Byggnader!D31),0) -> 0 | E29: =IF(AND(Byggnader!E16="En- och tvåbostadshus",E26>=90,E26<130),(Byggnader!E21+Byggnader!E31),0) -> 0 | F29: =IF(AND(Byggnader!F16="En- och tvåbostadshus",F26>=90,F26<130),(Byggnader!F21+Byggnader!F31),0) -> 0 | G29: =IF(AND(Byggnader!G16="En- och tvåbostadshus",G26>=90,G26<130),(Byggnader!G21+Byggnader!G31),0) -> 0 | H29: =IF(AND(Byggnader!H16="En- och tvåbostadshus",H26>=90,H26<130),(Byggnader!H21+Byggnader!H31),0) -> 0 | I29: =SUM(C29:H29) -> 0
A30: En- och tvåbostadshus ≥ 130 m² | C30: =IF(AND(Byggnader!C16="En- och tvåbostadshus",C26>=130),(Byggnader!C21+Byggnader!C31),0) -> 0 | D30: =IF(AND(Byggnader!D16="En- och tvåbostadshus",D26>=130),(Byggnader!D21+Byggnader!D31),0) -> 0 | E30: =IF(AND(Byggnader!E16="En- och tvåbostadshus",E26>=130),(Byggnader!E21+Byggnader!E31),0) -> 0 | F30: =IF(AND(Byggnader!F16="En- och tvåbostadshus",F26>=130),(Byggnader!F21+Byggnader!F31),0) -> 0 | G30: =IF(AND(Byggnader!G16="En- och tvåbostadshus",G26>=130),(Byggnader!G21+Byggnader!G31),0) -> 0 | H30: =IF(AND(Byggnader!H16="En- och tvåbostadshus",H26>=130),(Byggnader!H21+Byggnader!H31),0) -> 0 | I30: =SUM(C30:H30) -> 0
A31: Kontor | C31: =Byggnader!C24 -> 0 | D31: =Byggnader!D24 -> 0 | E31: =Byggnader!E24 -> 0 | F31: =Byggnader!F24 -> 0 | G31: =Byggnader!G24 -> 0 | H31: =Byggnader!H24 -> 0 | I31: =SUM(C31:H31) -> 0
A32: Utbildning | C32: =Byggnader!C25 -> 0 | D32: =Byggnader!D25 -> 0 | E32: =Byggnader!E25 -> 0 | F32: =Byggnader!F25 -> 0 | G32: =Byggnader!G25 -> 0 | H32: =Byggnader!H25 -> 0 | I32: =SUM(C32:H32) -> 0
A33: Sjukhus | C33: =Byggnader!C26 -> 0 | D33: =Byggnader!D26 -> 0 | E33: =Byggnader!E26 -> 0 | F33: =Byggnader!F26 -> 0 | G33: =Byggnader!G26 -> 0 | H33: =Byggnader!H26 -> 0 | I33: =SUM(C33:H33) -> 0
A34: Logi och restaurang | C34: =Byggnader!C27 -> 0 | D34: =Byggnader!D27 -> 0 | E34: =Byggnader!E27 -> 0 | F34: =Byggnader!F27 -> 0 | G34: =Byggnader!G27 -> 0 | H34: =Byggnader!H27 -> 0 | I34: =SUM(C34:H34) -> 0
A35: Idrott | C35: =Byggnader!C28 -> 0 | D35: =Byggnader!D28 -> 0 | E35: =Byggnader!E28 -> 0 | F35: =Byggnader!F28 -> 0 | G35: =Byggnader!G28 -> 0 | H35: =Byggnader!H28 -> 0 | I35: =SUM(C35:H35) -> 0
A36: Handel och kultur | C36: =Byggnader!C29 -> 0 | D36: =Byggnader!D29 -> 0 | E36: =Byggnader!E29 -> 0 | F36: =Byggnader!F29 -> 0 | G36: =Byggnader!G29 -> 0 | H36: =Byggnader!H29 -> 0 | I36: =SUM(C36:H36) -> 0
A37: Annan typ av energianvändande byggnad | C37: =Byggnader!C30 -> 0 | D37: =Byggnader!D30 -> 0 | E37: =Byggnader!E30 -> 0 | F37: =Byggnader!F30 -> 0 | G37: =Byggnader!G30 -> 0 | H37: =Byggnader!H30 -> 0 | I37: =SUM(C37:H37) -> 0
A38: Kontrollsumma (m²) | C38: =SUM(C27:C37) -> 0 | D38: =SUM(D27:D37) -> 0 | E38: =SUM(E27:E37) -> 0 | F38: =SUM(F27:F37) -> 0 | G38: =SUM(G27:G37) -> 0 | H38: =SUM(H27:H37) -> 0 | I38: =SUM(I27:I37) -> 0
A39: Kategoritypisk innetemperatur (°C) | C39: =IFERROR(SUMPRODUCT(C$27:C$37,'Regler BFS 2026'!$B$12:$B$22)/C$38,0) -> 0 | D39: =IFERROR(SUMPRODUCT(D$27:D$37,'Regler BFS 2026'!$B$12:$B$22)/D$38,0) -> 0 | E39: =IFERROR(SUMPRODUCT(E$27:E$37,'Regler BFS 2026'!$B$12:$B$22)/E$38,0) -> 0 | F39: =IFERROR(SUMPRODUCT(F$27:F$37,'Regler BFS 2026'!$B$12:$B$22)/F$38,0) -> 0 | G39: =IFERROR(SUMPRODUCT(G$27:G$37,'Regler BFS 2026'!$B$12:$B$22)/G$38,0) -> 0 | H39: =IFERROR(SUMPRODUCT(H$27:H$37,'Regler BFS 2026'!$B$12:$B$22)/H$38,0) -> 0 | I39: =IFERROR(SUMPRODUCT(I$27:I$37,'Regler BFS 2026'!$B$12:$B$22)/I$38,0) -> 0
A40: Kategoritypiskt uteluftsflöde (l/s,m²) | C40: =IFERROR(SUMPRODUCT(C$27:C$37,'Regler BFS 2026'!$C$12:$C$22)/C$38,0) -> 0 | D40: =IFERROR(SUMPRODUCT(D$27:D$37,'Regler BFS 2026'!$C$12:$C$22)/D$38,0) -> 0 | E40: =IFERROR(SUMPRODUCT(E$27:E$37,'Regler BFS 2026'!$C$12:$C$22)/E$38,0) -> 0 | F40: =IFERROR(SUMPRODUCT(F$27:F$37,'Regler BFS 2026'!$C$12:$C$22)/F$38,0) -> 0 | G40: =IFERROR(SUMPRODUCT(G$27:G$37,'Regler BFS 2026'!$C$12:$C$22)/G$38,0) -> 0 | H40: =IFERROR(SUMPRODUCT(H$27:H$37,'Regler BFS 2026'!$C$12:$C$22)/H$38,0) -> 0 | I40: =IFERROR(SUMPRODUCT(I$27:I$37,'Regler BFS 2026'!$C$12:$C$22)/I$38,0) -> 0
A41: Kategoritypisk internlast (W/m²) | C41: =IFERROR(SUMPRODUCT(C$27:C$37,'Regler BFS 2026'!$D$12:$D$22)/C$38,0) -> 0 | D41: =IFERROR(SUMPRODUCT(D$27:D$37,'Regler BFS 2026'!$D$12:$D$22)/D$38,0) -> 0 | E41: =IFERROR(SUMPRODUCT(E$27:E$37,'Regler BFS 2026'!$D$12:$D$22)/E$38,0) -> 0 | F41: =IFERROR(SUMPRODUCT(F$27:F$37,'Regler BFS 2026'!$D$12:$D$22)/F$38,0) -> 0 | G41: =IFERROR(SUMPRODUCT(G$27:G$37,'Regler BFS 2026'!$D$12:$D$22)/G$38,0) -> 0 | H41: =IFERROR(SUMPRODUCT(H$27:H$37,'Regler BFS 2026'!$D$12:$D$22)/H$38,0) -> 0 | I41: =IFERROR(SUMPRODUCT(I$27:I$37,'Regler BFS 2026'!$D$12:$D$22)/I$38,0) -> 0
A42: Kategoritypiskt energibehov tappvarmvatten (kWh/m²,år) | C42: =IFERROR(SUMPRODUCT(C$27:C$37,'Regler BFS 2026'!$E$12:$E$22)/C$38,0) -> 0 | D42: =IFERROR(SUMPRODUCT(D$27:D$37,'Regler BFS 2026'!$E$12:$E$22)/D$38,0) -> 0 | E42: =IFERROR(SUMPRODUCT(E$27:E$37,'Regler BFS 2026'!$E$12:$E$22)/E$38,0) -> 0 | F42: =IFERROR(SUMPRODUCT(F$27:F$37,'Regler BFS 2026'!$E$12:$E$22)/F$38,0) -> 0 | G42: =IFERROR(SUMPRODUCT(G$27:G$37,'Regler BFS 2026'!$E$12:$E$22)/G$38,0) -> 0 | H42: =IFERROR(SUMPRODUCT(H$27:H$37,'Regler BFS 2026'!$E$12:$E$22)/H$38,0) -> 0 | I42: =IFERROR(SUMPRODUCT(I$27:I$37,'Regler BFS 2026'!$E$12:$E$22)/I$38,0) -> 0
A44: Faktisk internlast och tappvarmvatten
...

Sheet Resultat
A1: Energiprestandatal och energiklass
A2: Kontrollberäkning av det Gripen räknar fram. Uppvärmningen klimatkorrigeras med energiindex i Byggnader C10.
A4: Byggnad | C4: =Byggnader!C12 -> Byggnad 1 | D4: =Byggnader!D12 -> Byggnad 2 | E4: =Byggnader!E12 -> Byggnad 3 | F4: =Byggnader!F12 -> Byggnad 4 | G4: =Byggnader!G12 -> Byggnad 5 | H4: =Byggnader!H12 -> Byggnad 6 | I4: Fastighet
A5: Egen beteckning | C5: =IF(Byggnader!C13="","",Byggnader!C13) | D5: =IF(Byggnader!D13="","",Byggnader!D13) | E5: =IF(Byggnader!E13="","",Byggnader!E13) | F5: =IF(Byggnader!F13="","",Byggnader!F13) | G5: =IF(Byggnader!G13="","",Byggnader!G13) | H5: =IF(Byggnader!H13="","",Byggnader!H13)
A6: A-temp (m²) | C6: =Normalisering!C26 -> 0 | D6: =Normalisering!D26 -> 0 | E6: =Normalisering!E26 -> 0 | F6: =Normalisering!F26 -> 0 | G6: =Normalisering!G26 -> 0 | H6: =Normalisering!H26 -> 0 | I6: =Normalisering!I26 -> 0
A7: Uppvärmning, klimatkorrigerad (kWh/år) | C7: =Normalisering!C120/Byggnader!$C$10 -> 0 | D7: =Normalisering!D120/Byggnader!$C$10 -> 0 | E7: =Normalisering!E120/Byggnader!$C$10 -> 0 | F7: =Normalisering!F120/Byggnader!$C$10 -> 0 | G7: =Normalisering!G120/Byggnader!$C$10 -> 0 | H7: =Normalisering!H120/Byggnader!$C$10 -> 0 | I7: =Normalisering!I120/Byggnader!$C$10 -> 0
A8: Tappvarmvatten (kWh/år) | C8: =Normalisering!C132 -> 0 | D8: =Normalisering!D132 -> 0 | E8: =Normalisering!E132 -> 0 | F8: =Normalisering!F132 -> 0 | G8: =Normalisering!G132 -> 0 | H8: =Normalisering!H132 -> 0 | I8: =Normalisering!I132 -> 0
A9: Övrig energi som ingår, el (kWh/år) | C9: =Normalisering!C139-Normalisering!C142 -> 0 | D9: =Normalisering!D139-Normalisering!D142 -> 0 | E9: =Normalisering!E139-Normalisering!E142 -> 0 | F9: =Normalisering!F139-Normalisering!F142 -> 0 | G9: =Normalisering!G139-Normalisering!G142 -> 0 | H9: =Normalisering!H139-Normalisering!H142 -> 0 | I9: =Normalisering!I139-Normalisering!I142 -> 0
A10: Komfortkyla och fjärrkyla (kWh/år) | C10: =Normalisering!C140+Normalisering!C141 -> 0 | D10: =Normalisering!D140+Normalisering!D141 -> 0 | E10: =Normalisering!E140+Normalisering!E141 -> 0 | F10: =Normalisering!F140+Normalisering!F141 -> 0 | G10: =Normalisering!G140+Normalisering!G141 -> 0 | H10: =Normalisering!H140+Normalisering!H141 -> 0 | I10: =Normalisering!I140+Normalisering!I141 -> 0
A11: Byggnadens energianvändning (kWh/år) | C11: =C7+C8+C9+C10 -> 0 | D11: =D7+D8+D9+D10 -> 0 | E11: =E7+E8+E9+E10 -> 0 | F11: =F7+F8+F9+F10 -> 0 | G11: =G7+G8+G9+G10 -> 0 | H11: =H7+H8+H9+H10 -> 0 | I11: =I7+I8+I9+I10 -> 0
A12: Byggnadens viktade energianvändning (kWh/år) | C12: =SUMPRODUCT(Normalisering!C112:C119,Mätdata!$E$47:$E$54)/Byggnader!$C$10+SUMPRODUCT(Normalisering!C124:C131,Mätdata!$E$47:$E$54)+'Regler BFS 2026'!$B$4*(C9+Normalisering!C140)+'Regler BFS 2026'!$B$6*Normalisering!C141 -> 0 | D12: =SUMPRODUCT(Normalisering!D112:D119,Mätdata!$E$47:$E$54)/Byggnader!$C$10+SUMPRODUCT(Normalisering!D124:D131,Mätdata!$E$47:$E$54)+'Regler BFS 2026'!$B$4*(D9+Normalisering!D140)+'Regler BFS 2026'!$B$6*Normalisering!D141 -> 0 | E12: =SUMPRODUCT(Normalisering!E112:E119,Mätdata!$E$47:$E$54)/Byggnader!$C$10+SUMPRODUCT(Normalisering!E124:E131,Mätdata!$E$47:$E$54)+'Regler BFS 2026'!$B$4*(E9+Normalisering!E140)+'Regler BFS 2026'!$B$6*Normalisering!E141 -> 0 | F12: =SUMPRODUCT(Normalisering!F112:F119,Mätdata!$E$47:$E$54)/Byggnader!$C$10+SUMPRODUCT(Normalisering!F124:F131,Mätdata!$E$47:$E$54)+'Regler BFS 2026'!$B$4*(F9+Normalisering!F140)+'Regler BFS 2026'!$B$6*Normalisering!F141 -> 0 | G12: =SUMPRODUCT(Normalisering!G112:G119,Mätdata!$E$47:$E$54)/Byggnader!$C$10+SUMPRODUCT(Normalisering!G124:G131,Mätdata!$E$47:$E$54)+'Regler BFS 2026'!$B$4*(G9+Normalisering!G140)+'Regler BFS 2026'!$B$6*Normalisering!G141 -> 0 | H12: =SUMPRODUCT(Normalisering!H112:H119,Mätdata!$E$47:$E$54)/Byggnader!$C$10+SUMPRODUCT(Normalisering!H124:H131,Mätdata!$E$47:$E$54)+'Regler BFS 2026'!$B$4*(H9+Normalisering!H140)+'Regler BFS 2026'!$B$6*Normalisering!H141 -> 0 | I12: =SUMPRODUCT(Normalisering!I112:I119,Mätdata!$E$47:$E$54)/Byggnader!$C$10+SUMPRODUCT(Normalisering!I124:I131,Mätdata!$E$47:$E$54)+'Regler BFS 2026'!$B$4*(I9+Normalisering!I140)+'Regler BFS 2026'!$B$6*Normalisering!I141 -> 0
A13: Energiprestandatal Etal (kWh/m²,år) | C13: =IF(C6=0,"",C12/C6) | D13: =IF(D6=0,"",D12/D6) | E13: =IF(E6=0,"",E12/E6) | F13: =IF(F6=0,"",F12/F6) | G13: =IF(G6=0,"",G12/G6) | H13: =IF(H6=0,"",H12/H6) | I13: =IF(I6=0,"",I12/I6)
A14: Energianvändning, oviktad (kWh/m²,år) | C14: =IF(C6=0,"",C11/C6) | D14: =IF(D6=0,"",D11/D6) | E14: =IF(E6=0,"",E11/E6) | F14: =IF(F6=0,"",F11/F6) | G14: =IF(G6=0,"",G11/G6) | H14: =IF(H6=0,"",H11/H6) | I14: =IF(I6=0,"",I11/I6)
A16: Högsta Etal per energiklass (kWh/m²,år)
A17: Klass A | C17: =IF(Normalisering!C$38=0,"",(SUMPRODUCT(Normalisering!C$27:C$37,'Regler BFS 2026'!$F$12:$F$22)+Byggnader!$C$7*SUMPRODUCT(Normalisering!C$27:C$37,'Regler BFS 2026'!$G$12:$G$22))/Normalisering!C$38) | D17: =IF(Normalisering!D$38=0,"",(SUMPRODUCT(Normalisering!D$27:D$37,'Regler BFS 2026'!$F$12:$F$22)+Byggnader!$C$7*SUMPRODUCT(Normalisering!D$27:D$37,'Regler BFS 2026'!$G$12:$G$22))/Normalisering!D$38) | E17: =IF(Normalisering!E$38=0,"",(SUMPRODUCT(Normalisering!E$27:E$37,'Regler BFS 2026'!$F$12:$F$22)+Byggnader!$C$7*SUMPRODUCT(Normalisering!E$27:E$37,'Regler BFS 2026'!$G$12:$G$22))/Normalisering!E$38) | F17: =IF(Normalisering!F$38=0,"",(SUMPRODUCT(Normalisering!F$27:F$37,'Regler BFS 2026'!$F$12:$F$22)+Byggnader!$C$7*SUMPRODUCT(Normalisering!F$27:F$37,'Regler BFS 2026'!$G$12:$G$22))/Normalisering!F$38) | G17: =IF(Normalisering!G$38=0,"",(SUMPRODUCT(Normalisering!G$27:G$37,'Regler BFS 2026'!$F$12:$F$22)+Byggnader!$C$7*SUMPRODUCT(Normalisering!G$27:G$37,'Regler BFS 2026'!$G$12:$G$22))/Normalisering!G$38) | H17: =IF(Normalisering!H$38=0,"",(SUMPRODUCT(Normalisering!H$27:H$37,'Regler BFS 2026'!$F$12:$F$22)+Byggnader!$C$7*SUMPRODUCT(Normalisering!H$27:H$37,'Regler BFS 2026'!$G$12:$G$22))/Normalisering!H$38) | I17: =IF(Normalisering!I$38=0,"",(SUMPRODUCT(Normalisering!I$27:I$37,'Regler BFS 2026'!$F$12:$F$22)+Byggnader!$C$7*SUMPRODUCT(Normalisering!I$27:I$37,'Regler BFS 2026'!$G$12:$G$22))/Normalisering!I$38)
A18: Klass B | C18: =IF(Normalisering!C$38=0,"",(SUMPRODUCT(Normalisering!C$27:C$37,'Regler BFS 2026'!$H$12:$H$22)+Byggnader!$C$7*SUMPRODUCT(Normalisering!C$27:C$37,'Regler BFS 2026'!$I$12:$I$22))/Normalisering!C$38) | D18: =IF(Normalisering!D$38=0,"",(SUMPRODUCT(Normalisering!D$27:D$37,'Regler BFS 2026'!$H$12:$H$22)+Byggnader!$C$7*SUMPRODUCT(Normalisering!D$27:D$37,'Regler BFS 2026'!$I$12:$I$22))/Normalisering!D$38) | E18: =IF(Normalisering!E$38=0,"",(SUMPRODUCT(Normalisering!E$27:E$37,'Regler BFS 2026'!$H$12:$H$22)+Byggnader!$C$7*SUMPRODUCT(Normalisering!E$27:E$37,'Regler BFS 2026'!$I$12:$I$22))/Normalisering!E$38) | F18: =IF(Normalisering!F$38=0,"",(SUMPRODUCT(Normalisering!F$27:F$37,'Regler BFS 2026'!$H$12:$H$22)+Byggnader!$C$7*SUMPRODUCT(Normalisering!F$27:F$37,'Regler BFS 2026'!$I$12:$I$22))/Normalisering!F$38) | G18: =IF(Normalisering!G$38=0,"",(SUMPRODUCT(Normalisering!G$27:G$37,'Regler BFS 2026'!$H$12:$H$22)+Byggnader!$C$7*SUMPRODUCT(Normalisering!G$27:G$37,'Regler BFS 2026'!$I$12:$I$22))/Normalisering!G$38) | H18: =IF(Normalisering!H$38=0,"",(SUMPRODUCT(Normalisering!H$27:H$37,'Regler BFS 2026'!$H$12:$H$22)+Byggnader!$C$7*SUMPRODUCT(Normalisering!H$27:H$37,'Regler BFS 2026'!$I$12:$I$22))/Normalisering!H$38) | I18: =IF(Normalisering!I$38=0,"",(SUMPRODUCT(Normalisering!I$27:I$37,'Regler BFS 2026'!$H$12:$H$22)+Byggnader!$C$7*SUMPRODUCT(Normalisering!I$27:I$37,'Regler BFS 2026'!$I$12:$I$22))/Normalisering!I$38)
